<?xml version="1.0"?>
<robot name="my_robot" xmlns:xacro="http://www.ros.org/wiki/xacro">


    <xacro:include filename="$(find my_robot_description)/urdf/robot.gazebo.xacro"/>
    <xacro:arg name="mesh_path" default="package://my_robot_description/meshes/"/>
    
    <xacro:property name="base_length" value="0.3"/>
    <xacro:property name="base_width"  value="0.3"/>
    <xacro:property name="base_height" value="0.2"/>
    <xacro:property name="base_mass"   value="5.0"/>

    <xacro:property name="wheel_radius" value="0.07"/>
    <xacro:property name="wheel_length" value="0.02"/>
    <xacro:property name="wheel_mass"   value="1.0"/>

    <xacro:property name="wheel_x_offset" value="0.1"/>
    <xacro:property name="wheel_y_offset" value="0.15"/>
    <xacro:property name="wheel_z_offset" value="-0.1"/>

    <xacro:property name="lidar_radius" value="0.06"/>
    <xacro:property name="lidar_length" value="0.04"/>
    <xacro:property name="lidar_mass"   value="0.1"/>
    <xacro:property name="lidar_z_offset" value="0.13"/>

    <xacro:property name="base_footprint_z" value="0.15"/>

    <link name="base_footprint"/>

    <joint name="base_footprint_joint" type="fixed">
        <parent link="base_footprint"/>
        <child link="base_link"/>
        <origin xyz="0 0 ${base_footprint_z}" rpy="0 0 0"/>
    </joint>

    <link name="base_link">
        <inertial>
            <origin xyz="0 0 0" rpy="0 0 0"/>
            <mass value="${base_mass}"/>
            <inertia
                ixx="${(1/12) * base_mass * (base_width*base_width + base_height*base_height)}"
                ixy="0.0" ixz="0.0"
                iyy="${(1/12) * base_mass * (base_length*base_length + base_height*base_height)}"
                iyz="0.0"
                izz="${(1/12) * base_mass * (base_length*base_length + base_width*base_width)}"/>
        </inertial>
        <visual>
            <geometry><box size="${base_length} ${base_width} ${base_height}"/></geometry>
            <material name="chassis_color"><color rgba="0.5 0.5 0.0 1.0"/></material>
        </visual>
        <collision>
            <geometry><box size="${base_length} ${base_width} ${base_height}"/></geometry>
        </collision>
    </link>

    <link name="lidar_link">
        <visual>
            <geometry><mesh filename="$(arg mesh_path)lidar.STL"/></geometry>
            <material name="lidar_gray"><color rgba="0.5 0.5 0.5 1.0"/></material>
        </visual>
        <collision>
            <geometry><cylinder radius="${lidar_radius}" length="${lidar_length}"/></geometry>
        </collision>
        <inertial>
            <mass value="${lidar_mass}"/>
            <inertia ixx="0.0001" ixy="0.0" ixz="0.0" iyy="0.0001" iyz="0.0" izz="0.0001"/>
        </inertial>
    </link>

    <joint name="lidar_joint" type="fixed">
        <parent link="base_link"/>
        <child link="lidar_link"/>
        <origin xyz="0 0 ${lidar_z_offset}" rpy="0 0 0"/>
    </joint>

    <xacro:macro name="wheel" params="prefix x_reflect y_reflect">
        <link name="${prefix}_wheel_link">
            <inertial>
                <mass value="${wheel_mass}"/>
                <inertia
                    ixx="${(1/12) * wheel_mass * (3*wheel_radius*wheel_radius + wheel_length*wheel_length)}"
                    ixy="0.0" ixz="0.0"
                    iyy="${(1/12) * wheel_mass * (3*wheel_radius*wheel_radius + wheel_length*wheel_length)}"
                    iyz="0.0"
                    izz="${(1/2) * wheel_mass * (wheel_radius*wheel_radius)}"/>
            </inertial>
            <visual>
                <origin xyz="0 0 0" rpy="1.5708 0 0"/>
                <geometry><cylinder radius="${wheel_radius}" length="${wheel_length}"/></geometry>
                <material name="wheel_color"><color rgba="0.0 0.0 0.0 1.0"/></material>
            </visual>
            <collision>
                <origin xyz="0 0 0" rpy="1.5708 0 0"/>
                <geometry><cylinder radius="${wheel_radius}" length="${wheel_length}"/></geometry>
            </collision>
        </link>
        <joint name="${prefix}_wheel_joint" type="continuous">
            <parent link="base_link"/>
            <child link="${prefix}_wheel_link"/>
            <origin xyz="${x_reflect * wheel_x_offset} ${y_reflect * wheel_y_offset} ${wheel_z_offset}" rpy="0 0 0"/>
            <axis xyz="0 1 0"/>
        </joint>
    </xacro:macro>

    <xacro:wheel prefix="left_front"  x_reflect="1"  y_reflect="1"/>
    <xacro:wheel prefix="right_front" x_reflect="1"  y_reflect="-1"/>
    <xacro:wheel prefix="left_back"   x_reflect="-1" y_reflect="1"/>
    <xacro:wheel prefix="right_back"  x_reflect="-1" y_reflect="-1"/>

</robot>
